Workbook
Name 번호: #REF!
Name 번호: #REF!
Name 봉투번호: #REF!
Name 봉투번호: #REF!
Name 봉투번호1: #REF!
Name 봉투번호1: #REF!
Name 헌금봉투2017: #REF!
Name 헌금봉투2017: #REF!
Name 헌금봉투번호2017: #REF!
Name 헌금봉투번호2017: #REF!

Sheet 결산양식
A1: 2025년 9월 결산
A2: 수정일 : 2025-10-19
A3: 계 정 과 목 | C3: 수 입 | F3: 계 정 과 목 | G3: 지 출 | I3: 비 고
C4: 전 월 | D4: 당 월 | G4: 전 월 | H4: 당 월
A5: 일 반 계 정 | B5: 십 일 조 | F5: 총 회 비
B6: 주 일 헌 금 | F6: 세계선교분담금
B7: 집 회 헌 금 | F7: 주 일 말 씀
B8: 감 사 헌 금 | F8: 전 도 집 회 비
B9: 세계선교분담금 | F9: 미디어선교회비
B10: 기 타 헌 금 | F10: 공 과 금
B11: 기 타 수 입 | F11: 운 영 비
B12: 예 금 이 자 | F12: 사 무 & 비 품
B13: 건축 대여금 회수 | F13: 차 량 유 지 비
F14: 시설&운영관리비
F15: 타 교 회 헌 금
F16: 부 서 지 원 비
F17: 기 타 비 용
F18: 대 여 금 | G18: 0
A19: 수 입 계 | C19: =SUM(C5:C13) -> 0 | D19: =SUM(D5:D13) -> 0 | F19: 지 출 계 | G19: =SUM(G5:G18) -> 0 | H19: =SUM(H5:H18) -> 0
A20: 전 월 금 | F20: 이 월 금 | G20: (a+b-c) | H20: =D20+D19-H19 -> 0 | L20: 25310626
A21: 교회학교 | B21: 후원회비 | F21: 교회학교후원비
B22: 차입금 | F22: 교회학교권역집회
B23: 차 입 금 | C23: =[1]결산양식!$D$23 -> 0 | D23: 0
A24: 수 입 계 | C24: =SUM(C21:C23) -> 0 | D24: =SUM(D21:D23) -> 0 | F24: 지 출 계 | G24: =SUM(G21:G23) -> 0 | H24: =SUM(H21:H23) -> 0
A25: 전 월 금 | F25: 이 월 금 | H25: =D25+D24-H24 -> 0 | L25: 990000
A26: 건축계정 | B26: 건 축 헌 금 | F26: 원 금 상 환
B27: 예 금 이 자 | F27: 대 출 이 자
B28: 기타(반환금) | F28: 기 타 비 용
B29: 승강기 헌금 | F29: 승 강 기
A30: 수 입 계 | C30: =SUM(C26:C29) -> 0 | D30: =SUM(D26:D29) -> 0 | F30: 지 출 계 | G30: =SUM(G26:G29) -> 0 | H30: =SUM(H26:H29) -> 0
A31: 전 월 금 | F31: 이 월 금 | H31: =D31+D30-H30 -> 0 | L31: 9125016
A32: 사랑 | B32: 사 랑 의 헌 금 | F32: 전 도 지 원 비 | G32: 0 | H32: 0
B33: 예 금 이 자 | F33: 경 조 사 비 | G33: 0 | H33: 0
B34: 기 타 수 입 | F34: 기 타 비 용 | G34: 0 | H34: 0
A35: 수 입 계 | C35: =SUM(C32:C34) -> 0 | D35: =SUM(D32:D34) -> 0 | F35: 지 출 계 | G35: =SUM(G32:G34) -> 0 | H35: =SUM(H32:H34) -> 0
A36: 전 월 금 | F36: 이 월 금 | H36: =D36+D35-H35 -> 0 | L36: 2409274
A37: 선교비 | B37: 선 교 회 비 | F37: 선 교 회 비
B38: 세계 선교회비 | F38: 세계 선교회비
A39: 수 입 계 | C39: =SUM(C37:C38) -> 0 | D39: =SUM(D37:D38) -> 0 | F39: 지 출 계 | G39: =SUM(G37:G38) -> 0 | H39: =SUM(H37:H38) -> 0
A40: 전 월 금 | F40: 이 월 금 | H40: =D40+D39-H39 -> 0 | L40: 1012000
...

Sheet 참여현황 및 주요관리항목 지출
A1: ◆ 월별 헌금 참여 현황
N2: 작성일 : 2025년 10월 19일
A3: 헌 금 항 목 | D3: 헌 금 참 여 현 황 (단위 : 명)
D4: 24. 12월 | E4: 1월 | F4: 2월 | G4: 3월 | H4: 4월 | I4: 5월 | J4: 6월 | K4: 7월 | L4: 8월 | M4: 9월 | N4: 10월 | O4: 11월 | P4: 12월 | Q4: 전월대비 | R4: 전전월대비
A5: 십 일 조 | C5: 인원
C6: 금액 | Q6: =M6/L6 -> #DIV/0! | R6: =M6/K6 -> #DIV/0!
A7: 주 일 헌 금 | C7: 인원
C8: 금액 | Q8: =M8/L8 -> #DIV/0! | R8: =M8/K8 -> #DIV/0!
A9: 세계선교 분담금 | C9: 인원
C10: 금액 | Q10: =M10/L10 -> #DIV/0! | R10: =M10/K10 -> #DIV/0!
A11: 교회학교후원회비 | C11: 인원
C12: 금액 | Q12: =M12/L12 -> #DIV/0! | R12: =M12/K12 -> #DIV/0!
A13: 건 축 헌 금 | C13: 인원
C14: 금액 | Q14: =M14/L14 -> #DIV/0! | R14: =M14/K14 -> #DIV/0!
A15: 사랑의 헌금 | C15: 인원
C16: 금액 | Q16: =M16/L16 -> #DIV/0! | R16: =M16/K16 -> #DIV/0!
A17: 선 교 회 비 | C17: 인원
C18: 금액 | Q18: =M18/L18 -> #DIV/0! | R18: =M18/K18 -> #DIV/0!
A19: 세계 선교회비 | C19: 인원
C20: 금액 | Q20: =M20/L20 -> #DIV/0! | R20: =M20/K20 -> #DIV/0!
A22: ◆ 주요 관리항목 지출 현황
A24: 제 목 | D24: 전기 요금 지출 현황 (단위 : 원)
D25: 1월 | E25: 2월 | F25: 3월 | G25: 4월 | H25: 5월 | I25: 6월 | J25: 7월 | K25: 8월 | L25: 9월 | M25: 10월 | N25: 11월 | O25: 12월 | P25: 합 계
A26: 전기요금 | B26: 2024' | C26: 기본 | P26: =SUM(D26:O26) -> 0 | Q26: =P26/12 -> 0
C27: 사용 | P27: =SUM(D27:O27) -> 0 | Q27: =P27/12 -> 0
C28: 부가세 전력기금등 | P28: =SUM(D28:O28) -> 0 | Q28: =P28/12 -> 0
C29: 합계 | P29: =SUM(D29:O29) -> 0 | Q29: =P29/12 -> 0
B30: 2025' | C30: 기본 | P30: =SUM(D30:O30) -> 0 | Q30: =P30/12 -> 0
C31: 사용 | P31: =SUM(D31:O31) -> 0 | Q31: =P31/12 -> 0
C32: 부가세 전력기금등 | P32: =SUM(D32:O32) -> 0 | Q32: =P32/12 -> 0
C33: 합계 | P33: =SUM(D33:O33) -> 0 | Q33: =P33/12 -> 0
B35: 최대부하/KWh | D35: 133 | E35: 140 | F35: 140 | G35: 140 | H35: 140 | I35: 140 | J35: 140 | K35: 140 | L35: 140 | M35: 140 | N35: 140 | O35: 140
B36: 7170 | D36: =$B36*D35 -> 953610 | E36: =$B36*E35 -> 1003800 | F36: =$B36*F35 -> 1003800 | G36: =$B36*G35 -> 1003800 | H36: =$B36*H35 -> 1003800 | I36: =$B36*I35 -> 1003800 | J36: =$B36*J35 -> 1003800 | K36: =$B36*K35 -> 1003800 | ... O36: =$B36*O35 -> 1003800

Sheet 주간보고자료
A1: 2025년 9월(3주) 주간 결산 보고
A2: Ⅰ 수입, 지출 현황 | R2: 작성일 : 2025-09-22 | T2: 단위 : 천원
A3: 계 정 과 목 | C3: 수 입 | J3: 차이 | L3: 계 정 과 목 | M3: 지 출 | T3: 차이
C4: 1주차 | D4: 2주차 | E4: 3주차 | F4: 4주차 | G4: 5주차 | H4: 누 적 | I4: 예 산 | M4: 1주차 | N4: 2주차 | O4: 3주차 | P4: 4주차 | Q4: 5주차 | R4: 누 적 | S4: 예 산
A5: 일 반 계 정 | B5: 십 일 조 | H5: =SUM(C5:G5) -> 0 | I5: =[3]종합!$B$6/12/1000 -> 25000 | J5: =H5-I5 -> -25000 | L5: 총 회 비 | R5: =SUM(M5:Q5) -> 0 | S5: =VLOOKUP(L5,[3]종합!$D:$F,2,0)/1000/12 -> 5500 | T5: =S5-R5 -> 5500
B6: 주 일 헌 금 | H6: =SUM(C6:G6) -> 0 | I6: =[3]종합!$B$9/12/1000 -> 2056.6667 | J6: =H6-I6 -> -2056.6667 | L6: 세계선교분담금 | R6: =SUM(M6:Q6) -> 0 | S6: 2800 | T6: =S6-R6 -> 2800
B7: 집 회 헌 금 | H7: =SUM(C7:G7) -> 0 | I7: =[3]종합!$B$10/12/1000 -> 887.5 | J7: =H7-I7 -> -887.5 | L7: 주 일 말 씀 | R7: =SUM(M7:Q7) -> 0 | S7: =VLOOKUP(L7,[3]종합!$D:$F,2,0)/1000/12 -> 525.48 | T7: =S7-R7 -> 525.48
B8: 감 사 헌 금 | H8: =SUM(C8:G8) -> 0 | I8: =[3]종합!$B$11/12/1000 -> 735.83333 | J8: =H8-I8 -> -735.83333 | L8: 전도집회비 | R8: =SUM(M8:Q8) -> 0 | S8: =VLOOKUP(L8,[3]종합!$D:$F,2,0)/1000/12 -> 830.83333 | T8: =S8-R8 -> 830.83333
B9: 세계선교분담금 | H9: =SUM(C9:G9) -> 0 | I9: =[3]종합!$B$7/12/1000 -> 1346.6667 | J9: =H9-I9 -> -1346.6667 | L9: 미디어 선교회비 | R9: =SUM(M9:Q9) -> 0 | S9: =VLOOKUP(L9,[3]종합!$D:$F,2,0)/1000/12 -> 200 | T9: =S9-R9 -> 200
B10: 기 타 헌 금 | H10: =SUM(C10:G10) -> 0 | I10: =[3]종합!$B$12/12/1000 -> 1250 | J10: =H10-I10 -> -1250 | L10: 공 과 금 | R10: =SUM(M10:Q10) -> 0 | S10: =VLOOKUP(L10,[3]종합!$D:$F,2,0)/1000/12 -> 2212.4167 | T10: =S10-R10 -> 2212.4167
B11: 기 타 수 입 | H11: =SUM(C11:G11) -> 0 | L11: 운 영 비 | R11: =SUM(M11:Q11) -> 0 | S11: =VLOOKUP(L11,[3]종합!$D:$F,2,0)/1000/12 -> 6609.1667 | T11: =S11-R11 -> 6609.1667
B12: 예 금 이 자 | H12: =SUM(C12:G12) -> 0 | J12: =H12-I12 -> 0 | L12: 사무&비품 | R12: =SUM(M12:Q12) -> 0 | S12: =VLOOKUP(L12,[3]종합!$D:$F,2,0)/1000/12 -> 531.41667 | T12: =S12-R12 -> 531.41667
B13: 차 입 금 | H13: =SUM(C13:G13) -> 0 | J13: =H13-I13 -> 0 | L13: 차량유지비 | R13: =SUM(M13:Q13) -> 0 | S13: =VLOOKUP(L13,[3]종합!$D:$F,2,0)/1000/12 -> 1368.4167 | T13: =S13-R13 -> 1368.4167
L14: 시설&운영관리비 | R14: =SUM(M14:Q14) -> 0 | S14: =VLOOKUP(L14,[3]종합!$D:$F,2,0)/1000/12 -> 5458.6142 | T14: =S14-R14 -> 5458.6142
L15: 타교회헌금 | R15: =SUM(M15:Q15) -> 0 | S15: =VLOOKUP(L15,[3]종합!$D:$F,2,0)/1000/12 -> 575 | T15: =S15-R15 -> 575
L16: 부서지원비 | R16: =SUM(M16:Q16) -> 0 | S16: =VLOOKUP(L16,[3]종합!$D:$F,2,0)/1000/12 -> 916.66667 | T16: =S16-R16 -> 916.66667
L17: 기 타 비 용1 | R17: =SUM(M17:Q17) -> 0 | S17: =24800/12 -> 2066.6667 | T17: =S17-R17 -> 2066.6667
L18: 대 여 금 | R18: =SUM(M18:Q18) -> 0 | T18: =S18-R18 -> 0
A19: 수 입 계 | C19: =SUM(C5:C13) -> 0 | D19: =SUM(D5:D13) -> 0 | E19: =SUM(E5:E13) -> 0 | F19: =SUM(F5:F13) -> 0 | G19: =SUM(G5:G13) -> 0 | H19: =SUM(H5:H13) -> 0 | I19: =SUM(I5:I13) -> 31276.667 | J19: =H19-I19 -> -31276.667 | L19: 지 출 계 | M19: =SUM(M5:M18) -> 0 | N19: =SUM(N5:N18) -> 0 | O19: =SUM(O5:O18) -> 0 | P19: =SUM(P5:P18) -> 0 | Q19: =SUM(Q5:Q18) -> 0 | R19: =SUM(R5:R18) -> 0 | S19: =SUM(S5:S18) -> 29594.678 | T19: =SUM(T5:T18) -> 29594.678
H20: 전월 잔액 | J20: 62423.136 | L20: 계정 잔액 | M20: =J20+C19-M19 -> 62423.136 | N20: =M20+D19-N19 -> 62423.136 | O20: =N20+E19-O19 -> 62423.136 | P20: =O20+F19-P19 -> 62423.136 | Q20: =P20+G19-Q19 -> 62423.136
A21: 교회학교 후원회비 | H21: =SUM(C21:G21) -> 0 | I21: =[3]종합!$B$8/12/1000 -> 786.66667 | J21: =H21-I21 -> -786.66667 | L21: 교회학교 후원비 | M21: 0 | N21: 0 | O21: 0 | P21: 0 | Q21: 0 | R21: =SUM(M21:Q21) -> 0 | S21: =VLOOKUP(L21,[4]종합!$D:$F,2,0)/1000/12 -> 1031.6667 | T21: =S21-R21 -> 1031.6667
H22: 전월 잔액 | J22: 5632.16 | L22: 계정 잔액 | M22: =J22+C21-M21 -> 5632.16 | N22: =M22+D21-N21 -> 5632.16 | O22: =N22+E21-O21 -> 5632.16 | P22: =O22+F21-P21 -> 5632.16 | Q22: =P22+G21-Q21 -> 5632.16
A23: 건축계정 | B23: 건 축 헌 금 | H23: =SUM(C23:G23) -> 0 | I23: =57200/12 -> 4766.6667 | J23: =H23-I23 -> -4766.6667 | L23: 원 금 상 환 | R23: =SUM(M23:Q23) -> 0 | S23: =VLOOKUP(L23,[3]종합!$D:$F,2,0)/1000/12 -> 4766.6667
B24: 회 별 헌 금 | H24: =SUM(C24:G24) -> 0 | I24: 0 | J24: =H24-I24 -> 0 | L24: 대 출 이 자 | R24: =SUM(M24:Q24) -> 0 | S24: =VLOOKUP(L24,[3]종합!$D:$F,2,0)/1000/12 -> 600 | T24: =S24-R24 -> 600
B25: 승강기헌금 | H25: =SUM(C25:G25) -> 0 | I25: =5000/12 -> 416.66667 | J25: =H25-I25 -> -416.66667 | L25: 토지개발등 | R25: =SUM(M25:Q25) -> 0
B26: 예 금 이 자 | H26: =SUM(C26:G26) -> 0 | J26: =H26-I26 -> 0 | L26: 기타잡비(갈릴리 숙소 분담금) | R26: =SUM(M26:Q26) -> 0
B27: 차 입 금 | H27: =SUM(C27:G27) -> 0 | L27: 승강기관련 | R27: =SUM(M27:Q27) -> 0
A28: 수 입 계 | C28: =SUM(C23:C27) -> 0 | D28: =SUM(D23:D27) -> 0 | E28: =SUM(E23:E27) -> 0 | F28: =SUM(F23:F27) -> 0 | G28: =SUM(G23:G27) -> 0 | H28: =SUM(H23:H27) -> 0 | I28: =SUM(I23:I27) -> 5183.3333 | J28: =SUM(J23:J27) -> -5183.3333 | L28: 지 출 계 | M28: =SUM(M23:M27) -> 0 | N28: =SUM(N23:N27) -> 0 | O28: =SUM(O23:O27) -> 0 | P28: =SUM(P23:P27) -> 0 | Q28: =SUM(Q23:Q27) -> 0 | R28: =SUM(R23:R27) -> 0 | S28: =SUM(S23:S27) -> 5366.6667 | T28: =SUM(T23:T27) -> 600
H29: 전월 잔액 | J29: 257676.19 | L29: 계정 잔액 | M29: =J29+(C28)-M28 -> 257676.19 | N29: =M29+D28-N28 -> 257676.19 | O29: =N29+E28-O28 -> 257676.19 | P29: =O29+F28-P28 -> 257676.19 | Q29: =P29+G28-Q28 -> 257676.19
A30: 사랑 | B30: 사랑의헌금 | H30: =SUM(C30:G30) -> 0 | I30: =3660/12 -> 305 | J30: =H30-I30 -> -305 | L30: 전도지원비 | R30: =SUM(M30:Q30) -> 0 | S30: =VLOOKUP(L30,[5]종합!$D:$F,2,0)/1000/12 -> 208.33333 | T30: =S30-R30 -> 208.33333
B31: 예 금 이 자 | H31: =SUM(C31:G31) -> 0 | J31: =H31-I31 -> 0 | L31: 경 조 사 비 | R31: =SUM(M31:Q31) -> 0 | S31: =VLOOKUP(L31,[3]종합!$D:$F,2,0)/1000/12 -> 235 | T31: =S31-R31 -> 235
B32: 기 타 수 입 | H32: =SUM(C32:G32) -> 0 | J32: =H32-I32 -> 0 | L32: 기 타 비 용3 | R32: =SUM(M32:Q32) -> 0 | T32: =S32-R32 -> 0
H33: =SUM(C33:G33) -> 0 | L33: 대 여 금 | R33: =SUM(M33:Q33) -> 0
A34: 수 입 계 | C34: =SUM(C30:C32) -> 0 | D34: =SUM(D30:D32) -> 0 | E34: =SUM(E30:E32) -> 0 | F34: =SUM(F30:F32) -> 0 | G34: =SUM(G30:G32) -> 0 | H34: =SUM(H30:H33) -> 0 | I34: =SUM(I30:I33) -> 305 | J34: =SUM(J30:J33) -> -305 | L34: 지 출 계 | M34: =SUM(M30:M33) -> 0 | N34: =SUM(N30:N33) -> 0 | O34: =SUM(O30:O33) -> 0 | P34: =SUM(P30:P33) -> 0 | Q34: =SUM(Q30:Q33) -> 0 | R34: =SUM(R30:R33) -> 0 | S34: =SUM(S30:S33) -> 443.33333 | T34: =SUM(T30:T33) -> 443.33333
H35: 전월 잔액 | J35: 1829.504 | L35: 계정 잔액 | M35: =J35+(C34+C35)-M34 -> 1829.504 | N35: =M35+D34-N34 -> 1829.504 | O35: =N35+E34-O34 -> 1829.504 | P35: =O35+F34-P34 -> 1829.504 | Q35: =P35+G34-Q34 -> 1829.504
A36: 선교비 | B36: 선 교 회 비 | H36: =SUM(C36:G36) -> 0 | I36: =7300/12 -> 608.33333 | J36: =H36-I36 -> -608.33333 | L36: 선교회비 | R36: =SUM(M36:Q36) -> 0 | S36: =VLOOKUP(L36,[3]종합!$D:$F,2,0)/1000/12 -> 608.33333
B37: 세계선교회비 | H37: =SUM(C37:G37) -> 0 | I37: =11200/12 -> 933.33333 | J37: =H37-I37 -> -933.33333 | L37: 세계선교회비 | R37: =SUM(M37:Q37) -> 0 | S37: =VLOOKUP(L37,[3]종합!$D:$F,2,0)/1000/12 -> 933.33333
B38: 기 타 수 입 | H38: =SUM(C38:G38) -> 0 | R38: =SUM(M38:Q38) -> 0
A39: 수 입 계 | C39: =SUM(C36:C38) -> 0 | D39: =SUM(D36:D38) -> 0 | E39: =SUM(E36:E38) -> 0 | F39: =SUM(F36:F38) -> 0 | G39: =SUM(G36:G38) -> 0 | H39: =SUM(H36:H38) -> 0 | I39: =SUM(I36:I38) -> 1541.6667 | J39: =SUM(J36:J38) -> -1541.6667 | L39: 지 출 계 | M39: =SUM(M36:M38) -> 0 | N39: =SUM(N36:N38) -> 0 | O39: =SUM(O36:O38) -> 0 | P39: =SUM(P36:P38) -> 0 | Q39: =SUM(Q36:Q38) -> 0 | R39: =SUM(R36:R38) -> 0 | S39: =SUM(S36:S38) -> 1541.6667 | T39: =SUM(T36:T38) -> 0
H40: 전월 잔액 | J40: 1635 | L40: 계정 잔액 | M40: =J40+C39-M39 -> 1635 | N40: =M40+D39-N39 -> 1635 | O40: =N40+E39-O39 -> 1635 | P40: =O40+F39-P39 -> 1635 | Q40: =P40+G39-Q39 -> 1635
...

Sheet 회계결산 표지
B2: 2025년 9월 회계 결산
B4: 1 | C4: 회계 결산서(임원모임 보고)
B5: 2 | C5: 수입,지출 원장 (일반,후원,사랑,선교,건축,해외후원,국내선교)
B6: 3 | C6: 헌금(수입) 현황
B7: 4 | C7: 지출 현황
B8: 5 | C8: 지출 결의서
B9: 6 | C9: 입금 전표 (현금 입금 전표)
B10: 7 | C10: 회별/부서별 회계 결산서
C11: 1) 은장회 (회비)
C12: 2) 봉사회 (회비)
C13: 3) 어머니회 (회비, 주방, 카페리마)
C14: 4) 청년회 (회비)
C15: 5) 중고등부 (후원회비 등)
C16: 6) 유초등부 (후원회비 등)
C17: 7) 미선부 (지원금)
C18: 8) 농선부 (지원금)
C19: 9) 친교부 (지원금)
C20: 10) 찬양대 (회비)
B21: 8 | C21: 통장 사본(각 결산서 및 계정)

Sheet Sheet1
C4: 작 성 자 | D4: 회 계 | E4: 총 무 | F4: 봉사회장 | G4: 담임목사
