Workbook
Name ㅁ: #REF!
Name ㅁ: #REF!
Name ㅁ: #REF!
Name ㅁㅁㅁ: #REF!
Name ㅁㅁㅁ: #REF!
Name ㅁㅁㅁ: #REF!
Name 번호: #REF!
Name 번호: #REF!
Name 번호: '헌금 봉투 번호 (2026)'!#REF!
Name 번호: #REF!
Name 봉투번호: #REF!
Name 봉투번호: #REF!
Name 봉투번호: '헌금 봉투 번호 (2026)'!#REF!
Name 봉투번호: #REF!
Name 봉투번호1: #REF!
Name 봉투번호1: #REF!
Name 봉투번호1: '헌금 봉투 번호 (2026)'!#REF!
Name 봉투번호1: #REF!
Name 헌금봉투2017: #REF!
Name 헌금봉투2017: #REF!
Name 헌금봉투2017: '헌금 봉투 번호 (2026)'!#REF!
Name 헌금봉투2017: #REF!
Name 헌금봉투번호2017: #REF!
Name 헌금봉투번호2017: #REF!
Name 헌금봉투번호2017: '헌금 봉투 번호 (2026)'!#REF!
Name 헌금봉투번호2017: #REF!

Sheet 주별 헌금 장부기록 1-7
B1: 2026년 2월 1~7 헌금
B2: 날 짜 | C2: 월 | D2: 봉투 번호 | E2: 이 름 | F2: 회 별 | G2: 구역 | H2: 이체 헌금 | I2: 십일조 (11000) | J2: 주일헌금 (11200) | K2: 후원회비 (13000) | L2: 집회헌금 (11400) | M2: 감사헌금 (11100) | N2: 기타헌금 (11500~ 11999) | O2: 건축헌금 (11300) | P2: 선교회비 (12000) | Q2: 세계선교 헌금 (12200) | R2: 사랑의헌금 (14000) | S2: 세계선교 분담금 (12100) | T2: 기타수입 (23000~ 25030) | U2: 비 고 | V2: 헌금 합계
B3: 46054 | C3: 2 | E3: =VLOOKUP($D3,'헌금 봉투 번호 (2026)'!$B$2:$E$326,2,FALSE) -> #N/A | F3: =VLOOKUP($D3,'헌금 봉투 번호 (2026)'!$B$2:$E$326,3,FALSE) -> #N/A | G3: =VLOOKUP($D3,'헌금 봉투 번호 (2026)'!$B$2:$E$326,4,FALSE) -> #N/A | V3: =SUM(I3:T3) -> 0
B4: 46054 | C4: 2 | E4: =VLOOKUP($D4,'헌금 봉투 번호 (2026)'!$B$2:$E$326,2,FALSE) -> #N/A | F4: =VLOOKUP($D4,'헌금 봉투 번호 (2026)'!$B$2:$E$326,3,FALSE) -> #N/A | G4: =VLOOKUP($D4,'헌금 봉투 번호 (2026)'!$B$2:$E$326,4,FALSE) -> #N/A | V4: =SUM(I4:T4) -> 0
B5: 46054 | C5: 2 | E5: =VLOOKUP($D5,'헌금 봉투 번호 (2026)'!$B$2:$E$326,2,FALSE) -> #N/A | F5: =VLOOKUP($D5,'헌금 봉투 번호 (2026)'!$B$2:$E$326,3,FALSE) -> #N/A | G5: =VLOOKUP($D5,'헌금 봉투 번호 (2026)'!$B$2:$E$326,4,FALSE) -> #N/A | V5: =SUM(I5:T5) -> 0
B6: 46054 | C6: 2 | E6: =VLOOKUP($D6,'헌금 봉투 번호 (2026)'!$B$2:$E$326,2,FALSE) -> #N/A | F6: =VLOOKUP($D6,'헌금 봉투 번호 (2026)'!$B$2:$E$326,3,FALSE) -> #N/A | G6: =VLOOKUP($D6,'헌금 봉투 번호 (2026)'!$B$2:$E$326,4,FALSE) -> #N/A | V6: =SUM(I6:T6) -> 0
B7: 46054 | C7: 2 | E7: =VLOOKUP($D7,'헌금 봉투 번호 (2026)'!$B$2:$E$326,2,FALSE) -> #N/A | F7: =VLOOKUP($D7,'헌금 봉투 번호 (2026)'!$B$2:$E$326,3,FALSE) -> #N/A | G7: =VLOOKUP($D7,'헌금 봉투 번호 (2026)'!$B$2:$E$326,4,FALSE) -> #N/A | V7: =SUM(I7:T7) -> 0
B8: 46054 | C8: 2 | E8: =VLOOKUP($D8,'헌금 봉투 번호 (2026)'!$B$2:$E$326,2,FALSE) -> #N/A | F8: =VLOOKUP($D8,'헌금 봉투 번호 (2026)'!$B$2:$E$326,3,FALSE) -> #N/A | G8: =VLOOKUP($D8,'헌금 봉투 번호 (2026)'!$B$2:$E$326,4,FALSE) -> #N/A | V8: =SUM(I8:T8) -> 0
B9: 46054 | C9: 2 | E9: =VLOOKUP($D9,'헌금 봉투 번호 (2026)'!$B$2:$E$326,2,FALSE) -> #N/A | F9: =VLOOKUP($D9,'헌금 봉투 번호 (2026)'!$B$2:$E$326,3,FALSE) -> #N/A | G9: =VLOOKUP($D9,'헌금 봉투 번호 (2026)'!$B$2:$E$326,4,FALSE) -> #N/A | V9: =SUM(I9:T9) -> 0
B10: 46054 | C10: 2 | E10: =VLOOKUP($D10,'헌금 봉투 번호 (2026)'!$B$2:$E$326,2,FALSE) -> #N/A | F10: =VLOOKUP($D10,'헌금 봉투 번호 (2026)'!$B$2:$E$326,3,FALSE) -> #N/A | G10: =VLOOKUP($D10,'헌금 봉투 번호 (2026)'!$B$2:$E$326,4,FALSE) -> #N/A | V10: =SUM(I10:T10) -> 0
B11: 46054 | C11: 2 | E11: =VLOOKUP($D11,'헌금 봉투 번호 (2026)'!$B$2:$E$326,2,FALSE) -> #N/A | F11: =VLOOKUP($D11,'헌금 봉투 번호 (2026)'!$B$2:$E$326,3,FALSE) -> #N/A | G11: =VLOOKUP($D11,'헌금 봉투 번호 (2026)'!$B$2:$E$326,4,FALSE) -> #N/A | V11: =SUM(I11:T11) -> 0
B12: 46054 | C12: 2 | E12: =VLOOKUP($D12,'헌금 봉투 번호 (2026)'!$B$2:$E$326,2,FALSE) -> #N/A | F12: =VLOOKUP($D12,'헌금 봉투 번호 (2026)'!$B$2:$E$326,3,FALSE) -> #N/A | G12: =VLOOKUP($D12,'헌금 봉투 번호 (2026)'!$B$2:$E$326,4,FALSE) -> #N/A | V12: =SUM(I12:T12) -> 0
B13: 46054 | C13: 2 | E13: =VLOOKUP($D13,'헌금 봉투 번호 (2026)'!$B$2:$E$326,2,FALSE) -> #N/A | F13: =VLOOKUP($D13,'헌금 봉투 번호 (2026)'!$B$2:$E$326,3,FALSE) -> #N/A | G13: =VLOOKUP($D13,'헌금 봉투 번호 (2026)'!$B$2:$E$326,4,FALSE) -> #N/A | V13: =SUM(I13:T13) -> 0
B14: 46054 | C14: 2 | E14: =VLOOKUP($D14,'헌금 봉투 번호 (2026)'!$B$2:$E$326,2,FALSE) -> #N/A | F14: =VLOOKUP($D14,'헌금 봉투 번호 (2026)'!$B$2:$E$326,3,FALSE) -> #N/A | G14: =VLOOKUP($D14,'헌금 봉투 번호 (2026)'!$B$2:$E$326,4,FALSE) -> #N/A | V14: =SUM(I14:T14) -> 0
... B58: 46054 | C58: 2 | E58: =VLOOKUP($D58,'헌금 봉투 번호 (2026)'!$B$2:$E$326,2,FALSE) -> #N/A | F58: =VLOOKUP($D58,'헌금 봉투 번호 (2026)'!$B$2:$E$326,3,FALSE) -> #N/A | G58: =VLOOKUP($D58,'헌금 봉투 번호 (2026)'!$B$2:$E$326,4,FALSE) -> #N/A | V58: =SUM(I58:T58) -> 0
B59: 46054 | C59: 2 | E59: =VLOOKUP($D59,'헌금 봉투 번호 (2026)'!$B$2:$E$326,2,FALSE) -> #N/A | F59: =VLOOKUP($D59,'헌금 봉투 번호 (2026)'!$B$2:$E$326,3,FALSE) -> #N/A | G59: =VLOOKUP($D59,'헌금 봉투 번호 (2026)'!$B$2:$E$326,4,FALSE) -> #N/A | H59: 이체 | V59: =SUM(I59:T59) -> 0
B60: 46054 | C60: 2 | E60: =VLOOKUP($D60,'헌금 봉투 번호 (2026)'!$B$2:$E$326,2,FALSE) -> #N/A | F60: =VLOOKUP($D60,'헌금 봉투 번호 (2026)'!$B$2:$E$326,3,FALSE) -> #N/A | G60: =VLOOKUP($D60,'헌금 봉투 번호 (2026)'!$B$2:$E$326,4,FALSE) -> #N/A | H60: 이체 | V60: =SUM(I60:T60) -> 0
B61: 46054 | C61: 2 | E61: =VLOOKUP($D61,'헌금 봉투 번호 (2026)'!$B$2:$E$326,2,FALSE) -> #N/A | F61: =VLOOKUP($D61,'헌금 봉투 번호 (2026)'!$B$2:$E$326,3,FALSE) -> #N/A | G61: =VLOOKUP($D61,'헌금 봉투 번호 (2026)'!$B$2:$E$326,4,FALSE) -> #N/A | H61: 이체 | V61: =SUM(I61:T61) -> 0
B62: 46054 | C62: 2 | E62: =VLOOKUP($D62,'헌금 봉투 번호 (2026)'!$B$2:$E$326,2,FALSE) -> #N/A | F62: =VLOOKUP($D62,'헌금 봉투 번호 (2026)'!$B$2:$E$326,3,FALSE) -> #N/A | G62: =VLOOKUP($D62,'헌금 봉투 번호 (2026)'!$B$2:$E$326,4,FALSE) -> #N/A | H62: 이체 | V62: =SUM(I62:T62) -> 0
B63: 46054 | C63: 2 | E63: =VLOOKUP($D63,'헌금 봉투 번호 (2026)'!$B$2:$E$326,2,FALSE) -> #N/A | F63: =VLOOKUP($D63,'헌금 봉투 번호 (2026)'!$B$2:$E$326,3,FALSE) -> #N/A | G63: =VLOOKUP($D63,'헌금 봉투 번호 (2026)'!$B$2:$E$326,4,FALSE) -> #N/A | H63: 이체 | V63: =SUM(I63:T63) -> 0
B64: 46054 | C64: 2 | E64: =VLOOKUP($D64,'헌금 봉투 번호 (2026)'!$B$2:$E$326,2,FALSE) -> #N/A | F64: =VLOOKUP($D64,'헌금 봉투 번호 (2026)'!$B$2:$E$326,3,FALSE) -> #N/A | G64: =VLOOKUP($D64,'헌금 봉투 번호 (2026)'!$B$2:$E$326,4,FALSE) -> #N/A | H64: 이체 | V64: =SUM(I64:T64) -> 0
B65: 46054 | C65: 2 | E65: =VLOOKUP($D65,'헌금 봉투 번호 (2026)'!$B$2:$E$326,2,FALSE) -> #N/A | F65: =VLOOKUP($D65,'헌금 봉투 번호 (2026)'!$B$2:$E$326,3,FALSE) -> #N/A | G65: =VLOOKUP($D65,'헌금 봉투 번호 (2026)'!$B$2:$E$326,4,FALSE) -> #N/A | H65: 이체 | V65: =SUM(I65:T65) -> 0
B66: 46054 | C66: 2 | E66: =VLOOKUP($D66,'헌금 봉투 번호 (2026)'!$B$2:$E$326,2,FALSE) -> #N/A | F66: =VLOOKUP($D66,'헌금 봉투 번호 (2026)'!$B$2:$E$326,3,FALSE) -> #N/A | G66: =VLOOKUP($D66,'헌금 봉투 번호 (2026)'!$B$2:$E$326,4,FALSE) -> #N/A | H66: 이체 | V66: =SUM(I66:T66) -> 0
B67: 46054 | C67: 2 | E67: =VLOOKUP($D67,'헌금 봉투 번호 (2026)'!$B$2:$E$326,2,FALSE) -> #N/A | F67: =VLOOKUP($D67,'헌금 봉투 번호 (2026)'!$B$2:$E$326,3,FALSE) -> #N/A | G67: =VLOOKUP($D67,'헌금 봉투 번호 (2026)'!$B$2:$E$326,4,FALSE) -> #N/A | H67: 이체 | V67: =SUM(I67:T67) -> 0
B68: 46054 | C68: 2 | E68: =VLOOKUP($D68,'헌금 봉투 번호 (2026)'!$B$2:$E$326,2,FALSE) -> #N/A | F68: =VLOOKUP($D68,'헌금 봉투 번호 (2026)'!$B$2:$E$326,3,FALSE) -> #N/A | G68: =VLOOKUP($D68,'헌금 봉투 번호 (2026)'!$B$2:$E$326,4,FALSE) -> #N/A | H68: 이체 | V68: =SUM(I68:T68) -> 0
B69: 46054 | C69: 2 | E69: =VLOOKUP($D69,'헌금 봉투 번호 (2026)'!$B$2:$E$326,2,FALSE) -> #N/A | F69: =VLOOKUP($D69,'헌금 봉투 번호 (2026)'!$B$2:$E$326,3,FALSE) -> #N/A | G69: =VLOOKUP($D69,'헌금 봉투 번호 (2026)'!$B$2:$E$326,4,FALSE) -> #N/A | H69: 이체 | V69: =SUM(I69:T69) -> 0
B70: 46054 | C70: 2 | E70: =VLOOKUP($D70,'헌금 봉투 번호 (2026)'!$B$2:$E$326,2,FALSE) -> #N/A | F70: =VLOOKUP($D70,'헌금 봉투 번호 (2026)'!$B$2:$E$326,3,FALSE) -> #N/A | G70: =VLOOKUP($D70,'헌금 봉투 번호 (2026)'!$B$2:$E$326,4,FALSE) -> #N/A | H70: 이체 | V70: =SUM(I70:T70) -> 0
... B119: 46054 | C119: 2 | E119: =VLOOKUP($D119,'헌금 봉투 번호 (2026)'!$B$2:$E$326,2,FALSE) -> #N/A | F119: =VLOOKUP($D119,'헌금 봉투 번호 (2026)'!$B$2:$E$326,3,FALSE) -> #N/A | G119: =VLOOKUP($D119,'헌금 봉투 번호 (2026)'!$B$2:$E$326,4,FALSE) -> #N/A | H119: 이체 | V119: =SUM(I119:T119) -> 0
V120: =SUM(I120:T120) -> 0
B122: =B1 -> 2026년 2월 1~7 헌금 | F122: 합계 | I122: =SUM(I3:I120) -> 0 | J122: =SUM(J3:J120) -> 0 | K122: =SUM(K3:K120) -> 0 | L122: =SUM(L3:L120) -> 0 | M122: =SUM(M3:M120) -> 0 | N122: =SUM(N3:N120) -> 0 | O122: =SUM(O3:O120) -> 0 | P122: =SUM(P3:P120) -> 0 | ... T122: =SUM(T3:T120) -> 0 | V122: =SUM(V3:V120) -> 0
T125: =T122-T124 -> 0
V136: =V138-V137 -> 0
G138: 현금 | I138: =SUM(I3:I58) -> 0 | J138: =SUM(J3:J58) -> 0 | K138: =SUM(K3:K58) -> 0 | L138: =SUM(L3:L58) -> 0 | M138: =SUM(M3:M58) -> 0 | N138: =SUM(N3:N58) -> 0 | O138: =SUM(O3:O58) -> 0 | P138: =SUM(P3:P58) -> 0 | ... V138: =SUM(V3:V58) -> 0
G139: 이체 | I139: =SUM(I59:I119) -> 0 | J139: =SUM(J59:J119) -> 0 | K139: =SUM(K59:K119) -> 0 | L139: =SUM(L59:L119) -> 0 | M139: =SUM(M59:M119) -> 0 | N139: =SUM(N59:N119) -> 0 | O139: =SUM(O59:O119) -> 0 | P139: =SUM(P59:P119) -> 0 | ... V139: =SUM(V59:V119) -> 0

Sheet 2026년 헌금 전체 누계
B1: 2026년 헌금 현황
B2: 헌금일 | C2: 월 | D2: 봉투 번호 | E2: 이 름 | F2: 회 별 | G2: 구역 | H2: 이체 헌금 | I2: 십일조 (11000) | J2: 주일헌금 (11200) | K2: 후원회비 (13000) | L2: 집회헌금 (11400) | M2: 감사헌금 (11100) | N2: 기타헌금 (11500~ 11999) | O2: 건축헌금 (11300) | P2: 선교회비 (12000) | Q2: 세계선교 헌금 (12200) | R2: 사랑의헌금 (14000) | S2: 세계선교 분담금 (12100) | T2: 기타수입 (23000~ 25030) | U2: 비 고 | V2: 헌금 합계
B3: 46054 | C3: 2
B4: 46054 | C4: 2
B5: 46054 | C5: 2
B6: 46054 | C6: 2
B7: 46054 | C7: 2
B8: 46054 | C8: 2
B9: 46054 | C9: 2
B10: 46054 | C10: 2
B11: 46054 | C11: 2
B12: 46054 | C12: 2
B13: 46054 | C13: 2
B14: 46054 | C14: 2
... B79: 46060 | C79: 2
B81: 2026년 2월 헌금 | F81: 합계 | I81: =SUM(I3:I80) -> 0 | J81: =SUM(J3:J80) -> 0 | K81: =SUM(K3:K80) -> 0 | L81: =SUM(L3:L80) -> 0 | M81: =SUM(M3:M80) -> 0 | N81: =SUM(N3:N80) -> 0 | O81: =SUM(O3:O80) -> 0 | P81: =SUM(P3:P80) -> 0 | ... V81: =SUM(V3:V80) -> 0

Sheet 인원집계
A1: 월 | B1: 2
B3: 데이터
A4: 회 별 | B4: 개수 : 십일조 (11000) | C4: 개수 : 주일헌금 (11200) | D4: 개수 : 세계선교헌금 | E4: 개수 : 후원회비 (13000) | F4: 개수 : 건축헌금 (11300) | G4: 개수 : 선교회비 (12000) | H4: 개수 : 세계선교분담금 | I4: 개수 : 사랑의헌금 (14000)
A5: 봉사회 | B5: 9 | C5: 6 | D5: 1 | E5: 2 | F5: 3 | G5: 1 | H5: 10 | I5: 2
A6: 어머니회 | B6: 9 | C6: 6 | D6: 2 | E6: 4 | F6: 3 | G6: 3 | H6: 11 | I6: 3
A7: 청년회 | B7: 2 | C7: 5 | F7: 2 | H7: 5
A8: 은장회 | B8: 14 | C8: 8 | D8: 1 | E8: 1 | H8: 12 | I8: 1
A9: 중고등부 | H9: 3
A10: 총합계 | B10: 34 | C10: 25 | D10: 4 | E10: 7 | F10: 8 | G10: 4 | H10: 41 | I10: 6
P12: 회 별 | Q12: 십일조 | R12: 주일헌금 | S12: 세계선교분담금 | T12: 후원회비 | U12: 건축헌금 | V12: 선교회비 | W12: 세계선교 | X12: 사랑의헌금
P13: 봉사회 | Q13: 9 | R13: 6 | S13: 1 | T13: 2 | U13: 3 | V13: 1 | W13: 10 | X13: 2
P14: 어머니회 | Q14: 9 | R14: 6 | S14: 2 | T14: 4 | U14: 3 | V14: 3 | W14: 11 | X14: 3
P15: 청년회 | Q15: 2 | R15: 5 | U15: 1 | W15: 5
P16: 은장회 | Q16: 14 | R16: 8 | S16: 1 | T16: 1 | W16: 12 | X16: 1
P17: 익 명
P18: 총합계 | Q18: =SUM(Q13:Q17) -> 34 | R18: =SUM(R13:R17) -> 25 | S18: =SUM(S13:S17) -> 4 | T18: =SUM(T13:T17) -> 7 | U18: =SUM(U13:U17) -> 7 | V18: =SUM(V13:V17) -> 4 | W18: =SUM(W13:W17) -> 38 | X18: =SUM(X13:X17) -> 6

Sheet 헌금 봉투 번호 (2026)
A1: 구 | B1: 번호 | C1: 이름 | D1: 회별 | E1: 구역 | F1: ㅁ | G1: aa | K1: No. | L1: 이름 | M1: 회별 | N1: 구역
B2: 1 | C2: 장관익 | D2: 봉사회 | E2: 11 | F2: =VLOOKUP(C2,L:N,2,0) -> 봉 | K2: 1 | L2: 임준석 | M2: 봉 | N2: 11
B3: 2 | C3: 김선우 | D3: 봉사회 | E3: 12 | F3: =VLOOKUP(C3,L:N,2,0) -> 봉 | K3: 2 | L3: 홍성범 | M3: 어 | N3: 11
B4: 3 | C4: 강승윤 | D4: 봉사회 | E4: 41 | F4: =VLOOKUP(C4,L:N,2,0) -> 봉 | K4: 3 | L4: 임지연 | M4: 청 | N4: 11
B5: 4 | C5: 곽상호 | D5: 봉사회 | E5: 22 | F5: =VLOOKUP(C5,L:N,2,0) -> 봉 | K5: 4 | L5: 서일환 | M5: 봉 | N5: 11
B6: 5 | C6: 권동구 | D6: 봉사회 | E6: 41 | F6: =VLOOKUP(C6,L:N,2,0) -> 봉 | K6: 5 | L6: 유애지 | M6: 어 | N6: 11
B7: 6 | C7: 김양곤 | D7: 봉사회 | E7: 41 | F7: =VLOOKUP(C7,L:N,2,0) -> 봉 | K7: 6 | L7: 장관익 | M7: 봉 | N7: 11
B8: 7 | C8: 이종복 | D8: 봉사회 | E8: 43 | F8: =VLOOKUP(C8,L:N,2,0) -> 봉 | K8: 7 | L8: 김동순 | M8: 어 | N8: 11
B9: 8 | C9: 지용남 | D9: 봉사회 | E9: 43 | F9: =VLOOKUP(C9,L:N,2,0) -> 봉 | K9: 8 | L9: 임용열 | M9: 봉 | N9: 11
B10: 9 | C10: 김상호 | D10: 봉사회 | E10: 43 | F10: =VLOOKUP(C10,L:N,2,0) -> 봉 | K10: 9 | L10: 이지영1 | M10: 어 | N10: 11
B11: 10 | C11: 김성권 | D11: 봉사회 | E11: 11 | F11: =VLOOKUP(C11,L:N,2,0) -> 봉 | K11: 10 | L11: 임한결 | M11: 청 | N11: 11
B12: 11 | C12: 김성령 | D12: 봉사회 | E12: 32 | F12: =VLOOKUP(C12,L:N,2,0) -> 봉 | K12: 11 | L12: 조경식 | M12: 봉 | N12: 11
B13: 12 | C13: 김세문 | D13: 봉사회 | E13: 21 | F13: =VLOOKUP(C13,L:N,2,0) -> 봉 | K13: 12 | L13: 손정미 | M13: 어 | N13: 11
... B44: 43 | C44: 이태현 | D44: 봉사회 | E44: 22 | F44: =VLOOKUP(C44,L:N,2,0) -> 봉 | K44: 43 | L44: 구민숙 | M44: 어 | N44: 12
A45: 추가 | B45: 44 | C45: 이동하 | D45: 봉사회 | E45: 21 | F45: =VLOOKUP(C45,L:N,2,0) -> 봉 | K45: 44 | L45: 정민구 | M45: 봉 | N45: 12
B46: 45 | C46: 이흥삼 | D46: 봉사회 | E46: 21 | F46: =VLOOKUP(C46,L:N,2,0) -> 봉 | K46: 45 | L46: 김옥례 | M46: 어 | N46: 12
B47: 46 | C47: 이희출 | D47: 봉사회 | E47: 22 | F47: =VLOOKUP(C47,L:N,2,0) -> 봉 | K47: 46 | L47: 김선우 | M47: 봉 | N47: 12
B48: 47 | C48: 양종우 | D48: 봉사회 | E48: 33 | F48: =VLOOKUP(C48,L:N,2,0) -> 봉 | K48: 47 | L48: 한윤숙 | M48: 어 | N48: 12
B49: 48 | C49: 임용열 | D49: 봉사회 | E49: 11 | F49: =VLOOKUP(C49,L:N,2,0) -> 봉 | K49: 48 | L49: 김형신 | M49: 봉 | N49: 12
B50: 49 | C50: 임준석 | D50: 봉사회 | E50: 11 | F50: =VLOOKUP(C50,L:N,2,0) -> 봉 | K50: 49 | L50: 김경아 | M50: 어 | N50: 12
B51: 50 | C51: 장승호 | D51: 봉사회 | E51: 42 | F51: =VLOOKUP(C51,L:N,2,0) -> 봉 | K51: 50 | L51: 이병래 | M51: 봉 | N51: 12
B52: 51 | C52: 전병철 | D52: 봉사회 | E52: 31 | F52: =VLOOKUP(C52,L:N,2,0) -> 봉 | K52: 51 | L52: 손미숙 | M52: 어 | N52: 12
B53: 52 | C53: 김종준 | D53: 봉사회 | E53: 31 | F53: =VLOOKUP(C53,L:N,2,0) -> 봉 | K53: 52 | L53: 이주언 | M53: 청 | N53: 12
B54: 53 | C54: 김대원 | D54: 봉사회 | E54: 31 | F54: =VLOOKUP(C54,L:N,2,0) -> 봉 | K54: 53 | L54: 서동진 | M54: 봉 | N54: 12
B55: 54 | C55: 정민구 | D55: 봉사회 | E55: 12 | F55: =VLOOKUP(C55,L:N,2,0) -> 봉 | K55: 54 | L55: 한상미 | M55: 어 | N55: 12
B56: 55 | C56: 조경식 | D56: 봉사회 | E56: 11 | F56: =VLOOKUP(C56,L:N,2,0) -> 봉 | K56: 55 | L56: 조수자 | M56: 어 | N56: 12
B57: 56 | C57: 조재근 | D57: 봉사회 | E57: 12 | F57: =VLOOKUP(C57,L:N,2,0) -> 봉 | K57: 56 | L57: 류순주 | M57: 어 | N57: 12
... B59: 58 | C59: 채병연 | D59: 봉사회 | E59: 43 | F59: =VLOOKUP(C59,L:N,2,0) -> 봉 | K59: 58 | L59: 이영희 | M59: 어 | N59: 12
A60: 추가 | B60: 59 | C60: 고현민 | D60: 봉사회 | E60: 32 | F60: =VLOOKUP(C60,L:N,2,0) -> 봉 | K60: 59 | L60: 양애란 | M60: 어 | N60: 12
B61: 60 | C61: 최준서 | D61: 봉사회 | E61: 22 | F61: =VLOOKUP(C61,L:N,2,0) -> 봉 | K61: 60 | L61: 임영택 | M61: 은 | N61: 12
B62: 61 | C62: 하종구 | D62: 봉사회 | E62: 32 | F62: =VLOOKUP(C62,L:N,2,0) -> 봉 | K62: 61 | L62: 서부돌 | M62: 은 | N62: 12
B63: 62 | C63: 정다움 | D63: 봉사회 | E63: 33 | F63: =VLOOKUP(C63,L:N,2,0) -> 봉 | K63: 62 | L63: 이재순 | M63: 은 | N63: 12
B64: 63 | C64: 황규진 | D64: 봉사회 | E64: 43 | F64: =VLOOKUP(C64,L:N,2,0) -> 봉 | K64: 63 | L64: 노무연 | M64: 은 | N64: 12
B65: 64 | C65: 황상진 | D65: 봉사회 | E65: 42 | F65: =VLOOKUP(C65,L:N,2,0) -> 봉 | K65: 64 | L65: 김영수 | M65: 청 | N65: 12
B66: 65 | C66: 황윤실 | D66: 봉사회 | E66: 42 | F66: =VLOOKUP(C66,L:N,2,0) -> 봉 | K66: 65 | L66: 전이우 | M66: 청 | N66: 12
B67: 66 | C67: 윤정훈 | D67: 봉사회 | E67: 33 | F67: =VLOOKUP(C67,L:N,2,0) -> 봉 | K67: 66 | L67: 장재희 | M67: 청 | N67: 12
B68: 67 | C68: 신두호 | D68: 봉사회 | E68: 31 | F68: =VLOOKUP(C68,L:N,2,0) -> 봉 | K68: 67 | L68: 전민지 | M68: 청 | N68: 12
B69: 68 | C69: 조성민 | D69: 봉사회 | E69: 41 | F69: =VLOOKUP(C69,L:N,2,0) -> 봉 | K69: 68 | L69: 조은지 | M69: 청 | N69: 12
B70: 69 | C70: 배종찬 | D70: 봉사회 | E70: 41 | F70: =VLOOKUP(C70,L:N,2,0) -> 봉 | K70: 69 | L70: 송경연 | M70: 청 | N70: 12
B71: 70 | C71: 진찬식 | D71: 봉사회 | E71: 32 | F71: =VLOOKUP(C71,L:N,2,0) -> 봉 | K71: 70 | L71: 김재홍 | M71: 봉 | N71: 21
...

Sheet 입금전표 (수요집금)
A1: 결재 | D1: 담 당 | E1: 회 계 | F1: 회 장
A3: 입 금 전 표
A4: 전표 No. : 수입-20260106-001
A5: 입금일자 | C5: 계 정 과 목 | D5: 금 액 | F5: 비 고
A6: 46029 | C6: 일반계정
A7: =A6 -> 46029 | C7: 교회학교 후원회비
A8: =A7 -> 46029 | C8: 건축헌금통장
A9: =A8 -> 46029 | C9: 사랑의헌금
A10: =A7 -> 46029 | C10: 선교회비
A11: =A8 -> 46029 | C11: 세계선교회비
A12: =A9 -> 46029 | C12: 구제헌금
A13: =A10 -> 46029 | C13: 고성후원헌금
A14: 합 계 | D14: =SUM(D6:E13) -> 0
A16: 2026년 1월 6일
A17: 대한예수교침례회 창원교회

Sheet 입금전표
A1: 결재 | D1: 담 당 | E1: 회 계 | F1: 회 장 | I1: 결재 | L1: 담 당 | M1: 회 계 | N1: 회 장
A3: 입 금 전 표 | I3: 입 금 전 표
A4: 전표 No. : 수입-20260208-002 | I4: 전표 No. : 수입-20260208-001
A5: 입금일자 | C5: 계 정 과 목 | D5: 금 액 | F5: 비 고 | I5: 입금일자 | K5: 계 정 과 목 | L5: 금 액 | N5: 비 고
A6: 46063 | C6: 일반계정 | I6: 46061 | K6: 일반계정
A7: =A6 -> 46063 | C7: 교회학교 후원회비 | I7: =I6 -> 46061 | K7: 교회학교 후원회비
A8: =A7 -> 46063 | C8: 건축헌금통장 | I8: =I7 -> 46061 | K8: 건축헌금통장
A9: =A8 -> 46063 | C9: 사랑의헌금 | I9: =I8 -> 46061 | K9: 사랑의헌금
A10: =A7 -> 46063 | C10: 선교회비 | I10: =I9 -> 46061 | K10: 선교회비
A11: =A8 -> 46063 | C11: 세계선교헌금 | I11: =I9 -> 46061 | K11: 세계선교헌금
A12: =A9 -> 46063 | C12: 세계선교분담금 | F12: 3780 | I12: =I9 -> 46061 | K12: 세계선교분담금 | N12: 3780
A13: =A10 -> 46063 | C13: E/V헌금 | F13: 63 | I13: =I10 -> 46061 | K13: E/V헌금 | N13: 63
A14: 합 계 | D14: =SUM(D6:E13) -> 0 | I14: 합 계 | L14: =SUM(L6:M13) -> 0 | O14: =L14+D14 -> 0
O15: =O14/1000-#REF! -> #REF!
A16: 46061 | I16: =A16 -> 46061
A17: 대한예수교침례회 창원교회 | I17: 대한예수교침례회 창원교회
