Workbook

Sheet Sheet3
A1: 지출월 | B1: (다중 항목)
A3: 합계 : 지출금액 | B3: 열 레이블
A4: 행 레이블 | B4: 1주차 | C4: 2주차 | D4: 3주차 | E4: (비어 있음) | F4: 4주차 | G4: 5주차 | H4: 총합계
A5: 기타 | B5: 12376.247 | C5: 126.8 | D5: 95 | G5: 425.6 | H5: 13023.647
A6: 기타 잡비 | B6: 52 | G6: 25.6 | H6: 77.6
A7: 교회행사(야외교제등) | B7: 1751.98 | C7: 76.8 | D7: 35 | H7: 1863.78
A8: 동계 관련 비용 | B8: 6276.734 | H8: 6276.734
A9: 회별, 부서별 반환금 | B9: 1235.973 | H9: 1235.973
A10: 교회 전체 임원 수련회 및 모임 관련 비용 | B10: 2860.76 | C10: 50 | H10: 2910.76
A11: 이체 오류 | B11: 198.8 | H11: 198.8
A12: 은장회 관련 비용 | D12: 60 | H12: 60
A13: 아르헨티나 심방여비(담임목사내외분) | G13: 400 | H13: 400
A14: 기타수입
A15: 1월 2주차 이체 헌금
A16: 동계수련회 헌금(1~3차)
A17: 동계수련회 식비잔액
A18: 임원수련회비 90명
A19: 임원수련회비 찬조금(8명)
A20: 총회 창원권역 동계수련회 지원비
A21: 동계수련회 현장접수비
A22: 동계수련회 매점수입(마산교회-30%)
A23: 동계수련회 기념품(머그컵)
A24: 성도교제의밤 포토존 수익금
A25: 동계수련회 포토존 수익금
... A36: 1월 5주차 헌금 (1/28) 잔돈
A37: 사무&비품 | C37: 100.85 | D37: 80 | G37: 208.52 | H37: 389.37
A38: 교회사무실 사무용품 | C38: 18.95 | G38: 30.52 | H38: 49.47
A39: 교회사무실 복사기 렌탈비 | C39: 53 | D39: 80 | G39: 120 | H39: 253
A40: 교회사무실 잡비 | C40: 28.9 | H40: 28.9
A41: 복사용지 구입비 | G41: 58 | H41: 58
A42: 선교회비 | D42: 690 | H42: 690
A43: 1월 2주차 이체 헌금
A44: 1월 2주차 헌금 (1/7)
A45: 1월 3주차 이체 헌금
A46: 1월 3주차 헌금(1/14)
A47: 선교회비 | D47: 690 | H47: 690
A48: 1월 4주차 이체 헌금
A49: 1월 4주차 헌금 (1/21)
A50: 1월 5주차 이체 헌금
A51: 1월 5주차 헌금 (1/28)
...

Sheet 통합계정
A1: 2026년 통합계정 장부(일반,후원회비,사랑, 선교)
J2: 단위 : 천원
A3: 지출월 | B3: 주차 | C3: 입금전표& 지출 결의 번호 | D3: 계정코드 | E3: 대분류 계정 항목 | F3: 적요 | G3: 수입금액 | H3: 지출금액 | I3: 수령자 | J3: 비고 | K3: 통합계좌 잔액
A4: 3월 | B4: 1주차 | E4: =VLOOKUP($D4,[1]계정코드!$A$5:$F$270,2,FALSE) -> #N/A | F4: =VLOOKUP($D4,[1]계정코드!$A$5:$F$270,4,FALSE) -> #N/A | K4: =#REF!+G4-H4 -> #REF!
A5: 3월 | B5: 1주차 | E5: =VLOOKUP($D5,[1]계정코드!$A$5:$F$270,2,FALSE) -> #N/A | F5: =VLOOKUP($D5,[1]계정코드!$A$5:$F$270,4,FALSE) -> #N/A | K5: =K4+G5-H5 -> #REF!
A6: 3월 | B6: 1주차 | E6: =VLOOKUP($D6,[1]계정코드!$A$5:$F$270,2,FALSE) -> #N/A | F6: =VLOOKUP($D6,[1]계정코드!$A$5:$F$270,4,FALSE) -> #N/A | K6: =K5+G6-H6 -> #REF!
A7: 3월 | B7: 1주차 | E7: =VLOOKUP($D7,[1]계정코드!$A$5:$F$270,2,FALSE) -> #N/A | F7: =VLOOKUP($D7,[1]계정코드!$A$5:$F$270,4,FALSE) -> #N/A | K7: =K6+G7-H7 -> #REF!
A8: 3월 | B8: 1주차 | E8: =VLOOKUP($D8,[1]계정코드!$A$5:$F$270,2,FALSE) -> #N/A | F8: =VLOOKUP($D8,[1]계정코드!$A$5:$F$270,4,FALSE) -> #N/A | K8: =K7+G8-H8 -> #REF!
A9: 3월 | B9: 1주차 | E9: =VLOOKUP($D9,[1]계정코드!$A$5:$F$270,2,FALSE) -> #N/A | F9: =VLOOKUP($D9,[1]계정코드!$A$5:$F$270,4,FALSE) -> #N/A | K9: =K8+G9-H9 -> #REF!
A10: 3월 | B10: 1주차 | E10: =VLOOKUP($D10,[1]계정코드!$A$5:$F$270,2,FALSE) -> #N/A | F10: =VLOOKUP($D10,[1]계정코드!$A$5:$F$270,4,FALSE) -> #N/A | K10: =K9+G10-H10 -> #REF!
A11: 3월 | B11: 1주차 | E11: =VLOOKUP($D11,[1]계정코드!$A$5:$F$270,2,FALSE) -> #N/A | F11: =VLOOKUP($D11,[1]계정코드!$A$5:$F$270,4,FALSE) -> #N/A | K11: =K10+G11-H11 -> #REF!
E12: =VLOOKUP($D12,[1]계정코드!$A$5:$F$270,2,FALSE) -> #N/A | F12: =VLOOKUP($D12,[1]계정코드!$A$5:$F$270,4,FALSE) -> #N/A | K12: =K11+G12-H12 -> #REF!
E13: =VLOOKUP($D13,[1]계정코드!$A$5:$F$270,2,FALSE) -> #N/A | F13: =VLOOKUP($D13,[1]계정코드!$A$5:$F$270,4,FALSE) -> #N/A | K13: =K12+G13-H13 -> #REF!
E14: =VLOOKUP($D14,[1]계정코드!$A$5:$F$270,2,FALSE) -> #N/A | F14: =VLOOKUP($D14,[1]계정코드!$A$5:$F$270,4,FALSE) -> #N/A | K14: =K13+G14-H14 -> #REF!
E15: =VLOOKUP($D15,[1]계정코드!$A$5:$F$270,2,FALSE) -> #N/A | F15: =VLOOKUP($D15,[1]계정코드!$A$5:$F$270,4,FALSE) -> #N/A | K15: =K14+G15-H15 -> #REF!
E16: =VLOOKUP($D16,[1]계정코드!$A$5:$F$270,2,FALSE) -> #N/A | F16: =VLOOKUP($D16,[1]계정코드!$A$5:$F$270,4,FALSE) -> #N/A | K16: =K15+G16-H16 -> #REF!
E17: =VLOOKUP($D17,[1]계정코드!$A$5:$F$270,2,FALSE) -> #N/A | F17: =VLOOKUP($D17,[1]계정코드!$A$5:$F$270,4,FALSE) -> #N/A | K17: =K16+G17-H17 -> #REF!
E18: =VLOOKUP($D18,[1]계정코드!$A$5:$F$270,2,FALSE) -> #N/A | F18: =VLOOKUP($D18,[1]계정코드!$A$5:$F$270,4,FALSE) -> #N/A | K18: =K17+G18-H18 -> #REF!
E19: =VLOOKUP($D19,[1]계정코드!$A$5:$F$270,2,FALSE) -> #N/A | F19: =VLOOKUP($D19,[1]계정코드!$A$5:$F$270,4,FALSE) -> #N/A | K19: =K18+G19-H19 -> #REF!
E20: =VLOOKUP($D20,[1]계정코드!$A$5:$F$270,2,FALSE) -> #N/A | F20: =VLOOKUP($D20,[1]계정코드!$A$5:$F$270,4,FALSE) -> #N/A | K20: =K19+G20-H20 -> #REF!
E21: =VLOOKUP($D21,[1]계정코드!$A$5:$F$270,2,FALSE) -> #N/A | F21: =VLOOKUP($D21,[1]계정코드!$A$5:$F$270,4,FALSE) -> #N/A | K21: =K20+G21-H21 -> #REF!
E22: =VLOOKUP($D22,[1]계정코드!$A$5:$F$270,2,FALSE) -> #N/A | F22: =VLOOKUP($D22,[1]계정코드!$A$5:$F$270,4,FALSE) -> #N/A | K22: =K21+G22-H22 -> #REF!
E23: =VLOOKUP($D23,[1]계정코드!$A$5:$F$270,2,FALSE) -> #N/A | F23: =VLOOKUP($D23,[1]계정코드!$A$5:$F$270,4,FALSE) -> #N/A | K23: =K22+G23-H23 -> #REF!
... E27: =VLOOKUP($D27,[1]계정코드!$A$5:$F$270,2,FALSE) -> #N/A | F27: =VLOOKUP($D27,[1]계정코드!$A$5:$F$270,4,FALSE) -> #N/A | K27: =K26+G27-H27 -> #REF!

Sheet 일반계정
A1: 2026년 일반계정 장부
J2: 단위 : 천원
A3: 지출월 | B3: 주차 | C3: 입금전표& 지출 결의 번호 | D3: 계정코드 | E3: 대분류 계정 항목 | F3: 적요 | G3: 수입금액 | H3: 지출금액 | I3: 수령자 | J3: 비고 | K3: 일반계정잔액 | L3: 구 계좌 잔액
A4: 3월 | B4: 1주차 | K4: =#REF!+G4-H4 -> #REF!
A5: 3월 | B5: 1주차 | K5: =K4+G5-H5 -> #REF!
A6: 3월 | B6: 1주차 | K6: =K5+G6-H6 -> #REF!
A7: 3월 | B7: 1주차 | K7: =K6+G7-H7 -> #REF!
A8: 3월 | B8: 1주차 | K8: =K7+G8-H8 -> #REF!
A9: 3월 | B9: 1주차 | K9: =K8+G9-H9 -> #REF!
A10: 3월 | B10: 1주차 | K10: =K9+G10-H10 -> #REF!
A11: 3월 | B11: 1주차 | K11: =K10+G11-H11 -> #REF!
A12: 3월 | B12: 1주차 | K12: =K11+G12-H12 -> #REF!
A13: 3월 | B13: 1주차 | K13: =K12+G13-H13 -> #REF!
A14: 3월 | B14: 1주차 | K14: =K13+G14-H14 -> #REF!
A15: 3월 | B15: 1주차 | K15: =K14+G15-H15 -> #REF!
A16: 3월 | B16: 1주차 | K16: =K15+G16-H16 -> #REF!
... A47: 3월 | B47: 1주차 | K47: =K46+G47-H47 -> #REF!
K48: =K47+G48-H48 -> #REF!
K49: =K48+G49-H49 -> #REF!
K50: =K49+G50-H50 -> #REF!
K51: =K50+G51-H51 -> #REF!
K52: =K51+G52-H52 -> #REF!
K53: =K52+G53-H53 -> #REF!
K54: =K53+G54-H54 -> #REF!

Sheet 교회학교후원회비
A1: 2026년 교회학교후원회비계정 장부
J2: 단위 : 천원
A3: 지출월 | B3: 주차 | C3: 입금전표& 지출 결의 번호 | D3: 계정코드 | E3: 대분류 계정 항목 | F3: 적요 | G3: 수입금액 | H3: 지출금액 | I3: 수령자 | J3: 비고 | K3: 계정잔액
K4: =#REF!+G4-H4 -> #REF!
K5: =K4+G5-H5 -> #REF!
K6: =K5+G6-H6 -> #REF!
K7: =K6+G7-H7 -> #REF!
K8: =K7+G8-H8 -> #REF!
K9: =K8+G9-H9 -> #REF!
K10: =K9+G10-H10 -> #REF!
K11: =K10+G11-H11 -> #REF!
K12: =K11+G12-H12 -> #REF!
K13: =K12+G13-H13 -> #REF!
K14: =K13+G14-H14 -> #REF!
K15: =K14+G15-H15 -> #REF!
K16: =K15+G16-H16 -> #REF!
... K31: =K30+G31-H31 -> #REF!
A32: 2월 교회학교후원회비 결산 금액 | G32: =SUM(G4:G31) -> 0 | H32: =SUM(H4:H31) -> 0 | I32: 이월금 | J32: =K31 -> #REF!

Sheet 사랑의헌금
A1: 2026년 사랑의헌금계정 장부
A3: 지출월 | B3: 주차 | C3: 입금전표& 지출 결의 번호 | D3: 계정코드 | E3: 대분류 계정 항목 | F3: 적요
K4: =#REF!+G4-H4 -> #REF!
K5: =K4+G5-H5 -> #REF!
K6: =K5+G6-H6 -> #REF!
K7: =K6+G7-H7 -> #REF!
K8: =K7+G8-H8 -> #REF!
K9: =K8+G9-H9 -> #REF!
K10: =K9+G10-H10 -> #REF!
K11: =K10+G11-H11 -> #REF!
K12: =K11+G12-H12 -> #REF!
K13: =K12+G13-H13 -> #REF!
K14: =K13+G14-H14 -> #REF!
K15: =K14+G15-H15 -> #REF!
K16: =K15+G16-H16 -> #REF!
... K18: =K17+G18-H18 -> #REF!
A19: 2월 사랑의헌금 결산 금액 | G19: =SUM(G4:G18) -> 0 | H19: =SUM(H4:H18) -> 0 | I19: 이월금 | J19: =K18 -> #REF!

Sheet 선교회비
A1: 2026년 선교회비(세계선교포함) 계정 장부
J2: 단위 : 천원
A3: 지출월 | B3: 주차 | C3: 입금전표& 지출 결의 번호 | D3: 계정코드 | E3: 대분류 계정 항목 | F3: 적요 | G3: 수입금액 | H3: 지출금액 | I3: 수령자 | J3: 비고 | K3: 계정잔액
A4: 2월 | B4: 1주차 | K4: =#REF!+G4-H4 -> #REF!
A5: 2월 | B5: 1주차 | K5: =K4+G5-H5 -> #REF!
A6: 2월 | B6: 1주차 | K6: =K5+G6-H6 -> #REF!
A7: 2월 | B7: 1주차 | K7: =K6+G7-H7 -> #REF!
A8: 2월 | B8: 1주차 | K8: =K7+G8-H8 -> #REF!
A9: 2월 | B9: 1주차 | K9: =K8+G9-H9 -> #REF!
A10: 2월 | B10: 2주차 | K10: =K9+G10-H10 -> #REF!
A11: 2월 | B11: 2주차 | K11: =K10+G11-H11 -> #REF!
A12: 2월 | B12: 2주차 | K12: =K11+G12-H12 -> #REF!
A13: 2월 | B13: 2주차 | K13: =K12+G13-H13 -> #REF!
A14: 2월 | B14: 2주차 | K14: =K13+G14-H14 -> #REF!
A15: 2월 | B15: 2주차 | K15: =K14+G15-H15 -> #REF!
A16: 2월 | B16: 2주차 | K16: =K15+G16-H16 -> #REF!
... A39: 2월 | B39: 4주차 | K39: =K38+G39-H39 -> #REF!
A40: 2월 선교회비 결산 금액 | G40: =SUM(G4:G39) -> 0 | H40: =SUM(H4:H39) -> 0 | I40: 이월금 | J40: =K39 -> #REF!

Sheet 건축계정
A1: 2026년 건축계정 장부
J2: 단위 : 천원
A3: 지출월 | B3: 주차 | C3: 입금전표& 지출 결의 번호 | D3: 계정코드 | E3: 대분류 계정 항목 | F3: 적요 | G3: 수입금액 | H3: 지출금액 | I3: 수령자 | J3: 비고 | K3: 계정잔액
A4: 2월 | B4: 1주차 | K4: =#REF!+G4-H4 -> #REF!
A5: 2월 | B5: 1주차 | K5: =K4+G5-H5 -> #REF!
A6: 2월 | B6: 1주차 | K6: =K5+G6-H6 -> #REF!
A7: 2월 | B7: 1주차 | K7: =K6+G7-H7 -> #REF!
A8: 2월 | B8: 1주차 | K8: =K7+G8-H8 -> #REF!
A9: 2월 | B9: 1주차 | K9: =K8+G9-H9 -> #REF!
A10: 2월 | B10: 1주차 | K10: =K9+G10-H10 -> #REF!
A11: 2월 | B11: 1주차 | K11: =K10+G11-H11 -> #REF!
A12: 2월 | B12: 1주차 | K12: =K11+G12-H12 -> #REF!
A13: 2월 | B13: 1주차 | K13: =K12+G13-H13 -> #REF!
A14: 2월 | B14: 1주차 | K14: =K13+G14-H14 -> #REF!
A15: 2월 | B15: 1주차 | K15: =K14+G15-H15 -> #REF!
A16: 2월 | B16: 2주차 | K16: =K15+G16-H16 -> #REF!
... A66: 2월 | B66: 4주차 | K66: =K65+G66-H66 -> #REF!
A67: 2월 건축헌금 결산 금액 | G67: =SUM(G4:G66)-390 -> -390 | H67: =SUM(H4:H66)-20 -> -20 | I67: 이월금 | J67: =K66-390 -> #REF!
A68: 3월 | B68: 1주차 | C68: 46082 | D68: 11300 | E68: =VLOOKUP($D68,[1]계정코드!$A$5:$F$270,2,FALSE) -> 건축헌금 | F68: 3월1째주 이체 헌금 | G68: 30 | K68: =K66+G68-H68 -> #REF!
A69: 3월 | B69: 1주차 | C69: 46082 | D69: 11300 | E69: =VLOOKUP($D69,[1]계정코드!$A$5:$F$270,2,FALSE) -> 건축헌금 | F69: 3월1째주 이체 헌금 | G69: 300 | K69: =K68+G69-H69 -> #REF!
A70: 3월 | B70: 1주차 | C70: 수입-20260301-001 | D70: 11300 | E70: =VLOOKUP($D70,[1]계정코드!$A$5:$F$270,2,FALSE) -> 건축헌금 | F70: 3월1째주 헌금(3/1) | G70: 4330 | K70: =K69+G70-H70 -> #REF!
A71: 3월 | B71: 1주차 | C71: 46084 | D71: 11300 | E71: =VLOOKUP($D71,[1]계정코드!$A$5:$F$270,2,FALSE) -> 건축헌금 | F71: 3월1째주 이체 헌금 | G71: 150 | K71: =K70+G71-H71 -> #REF!
A72: 3월 | B72: 1주차 | C72: 46084 | D72: 11300 | E72: =VLOOKUP($D72,[1]계정코드!$A$5:$F$270,2,FALSE) -> 건축헌금 | F72: 3월1째주 이체 헌금 | G72: 200 | K72: =K71+G72-H72 -> #REF!
A73: 3월 | B73: 1주차 | C73: 46084 | D73: 62600 | E73: =VLOOKUP($D73,[1]계정코드!$A$5:$F$270,2,FALSE) -> 건축 | F73: =VLOOKUP($D73,[1]계정코드!$A$5:$F$270,4,FALSE) -> 매입부지 개발 관련 | H73: 200 | J73: 신축공사현장대리인 | K73: =K72+G73-H73 -> #REF!

Sheet 승강기계정
A1: 2026년 승강기 계정 장부
J2: 단위 : 천원
A3: 지출월 | B3: 주차 | C3: 입금전표& 지출 결의 번호 | D3: 계정코드 | E3: 대분류 계정 항목 | F3: 적요 | G3: 수입금액 | H3: 지출금액 | I3: 수령자 | J3: 비고 | K3: 승강기 계좌잔액
A4: 2월 | B4: 1주차 | K4: =#REF!+G4-H4 -> #REF!
A5: 2월 | B5: 1주차 | K5: =K4+G5-H5 -> #REF!
A6: 2월 | B6: 4주차 | K6: =K5+G6-H6 -> #REF!
A7: 2월 | B7: 4주차 | K7: =K6+G7-H7 -> #REF!
A8: 2월 승강기헌금 결산 금액 | G8: =SUM(G4:G7) -> 0 | H8: =SUM(H4:H7) -> 0 | I8: 이월금 | J8: =K7 -> #REF!

Sheet 해외후원
A1: 2026년 해외후원참여헌금 계정 장부
J2: 단위 : 천원
A3: 지출월 | B3: 주차 | C3: 입금전표& 지출 결의 번호 | D3: 계정코드 | E3: 대분류 계정 항목 | F3: 적요 | G3: 수입금액 | H3: 지출금액 | I3: 수령자 | J3: 비고 | K3: 계정잔액
A4: 2월 해외후원 결산 금액 | G4: =SUM(#REF!)-307+390-20 -> #REF! | H4: =SUM(#REF!)-307 -> #REF! | I4: 이월금 | J4: =#REF!+390 -> #REF!
E5: =VLOOKUP($D5,[1]계정코드!$A$5:$F$270,2,FALSE) -> #N/A | F5: =VLOOKUP($D5,[1]계정코드!$A$5:$F$270,4,FALSE) -> #N/A | K5: =#REF!+G5-H5 -> #REF!
E6: =VLOOKUP($D6,[1]계정코드!$A$5:$F$270,2,FALSE) -> #N/A | F6: =VLOOKUP($D6,[1]계정코드!$A$5:$F$270,4,FALSE) -> #N/A | K6: =K5+G6-H6 -> #REF!
E7: =VLOOKUP($D7,[1]계정코드!$A$5:$F$270,2,FALSE) -> #N/A | F7: =VLOOKUP($D7,[1]계정코드!$A$5:$F$270,4,FALSE) -> #N/A | K7: =K6+G7-H7 -> #REF!
E8: =VLOOKUP($D8,[1]계정코드!$A$5:$F$270,2,FALSE) -> #N/A | F8: =VLOOKUP($D8,[1]계정코드!$A$5:$F$270,4,FALSE) -> #N/A | K8: =K7+G8-H8 -> #REF!
E9: =VLOOKUP($D9,[1]계정코드!$A$5:$F$270,2,FALSE) -> #N/A | F9: =VLOOKUP($D9,[1]계정코드!$A$5:$F$270,4,FALSE) -> #N/A | K9: =K8+G9-H9 -> #REF!
E10: =VLOOKUP($D10,[1]계정코드!$A$5:$F$270,2,FALSE) -> #N/A | F10: =VLOOKUP($D10,[1]계정코드!$A$5:$F$270,4,FALSE) -> #N/A | K10: =K9+G10-H10 -> #REF!
E11: =VLOOKUP($D11,[1]계정코드!$A$5:$F$270,2,FALSE) -> #N/A | F11: =VLOOKUP($D11,[1]계정코드!$A$5:$F$270,4,FALSE) -> #N/A | K11: =K10+G11-H11 -> #REF!
E12: =VLOOKUP($D12,[1]계정코드!$A$5:$F$270,2,FALSE) -> #N/A | F12: =VLOOKUP($D12,[1]계정코드!$A$5:$F$270,4,FALSE) -> #N/A | K12: =K11+G12-H12 -> #REF!
E13: =VLOOKUP($D13,[1]계정코드!$A$5:$F$270,2,FALSE) -> #N/A | F13: =VLOOKUP($D13,[1]계정코드!$A$5:$F$270,4,FALSE) -> #N/A | K13: =K12+G13-H13 -> #REF!
E14: =VLOOKUP($D14,[1]계정코드!$A$5:$F$270,2,FALSE) -> #N/A | F14: =VLOOKUP($D14,[1]계정코드!$A$5:$F$270,4,FALSE) -> #N/A | K14: =K13+G14-H14 -> #REF!
E15: =VLOOKUP($D15,[1]계정코드!$A$5:$F$270,2,FALSE) -> #N/A | F15: =VLOOKUP($D15,[1]계정코드!$A$5:$F$270,4,FALSE) -> #N/A | K15: =K14+G15-H15 -> #REF!
E16: =VLOOKUP($D16,[1]계정코드!$A$5:$F$270,2,FALSE) -> #N/A | F16: =VLOOKUP($D16,[1]계정코드!$A$5:$F$270,4,FALSE) -> #N/A | K16: =K15+G16-H16 -> #REF!
E17: =VLOOKUP($D17,[1]계정코드!$A$5:$F$270,2,FALSE) -> #N/A | F17: =VLOOKUP($D17,[1]계정코드!$A$5:$F$270,4,FALSE) -> #N/A | K17: =K16+G17-H17 -> #REF!
... E44: =VLOOKUP($D44,[1]계정코드!$A$5:$F$270,2,FALSE) -> #N/A | F44: =VLOOKUP($D44,[1]계정코드!$A$5:$F$270,4,FALSE) -> #N/A | K44: =K43+G44-H44 -> #REF!

Sheet 국내선교
A1: 2026년 국내선교 계정 장부
J2: 단위 : 천원
A3: 지출월 | B3: 주차 | C3: 입금전표& 지출 결의 번호 | D3: 계정코드 | E3: 대분류 계정 항목 | F3: 적요 | G3: 수입금액 | H3: 지출금액 | I3: 수령자 | J3: 비고 | K3: 계정잔액
A4: 2월 | B4: 4주차 | E4: =VLOOKUP($D4,[1]계정코드!$A$5:$F$270,2,FALSE) -> #N/A | F4: =VLOOKUP($D4,[1]계정코드!$A$5:$F$270,4,FALSE) -> #N/A | K4: =#REF!+G4-H4 -> #REF!
A5: 2월 국내선교 결산 금액 | G5: =SUM(G4) -> 0 | H5: =SUM(H4) -> 0 | I5: 이월금 | J5: =K4 -> #REF!
E6: =VLOOKUP($D6,[1]계정코드!$A$5:$F$270,2,FALSE) -> #N/A | F6: =VLOOKUP($D6,[1]계정코드!$A$5:$F$270,4,FALSE) -> #N/A | K6: =K4+G6-H6 -> #REF!
E7: =VLOOKUP($D7,[1]계정코드!$A$5:$F$270,2,FALSE) -> #N/A | F7: =VLOOKUP($D7,[1]계정코드!$A$5:$F$270,4,FALSE) -> #N/A | K7: =K6+G7-H7 -> #REF!
E8: =VLOOKUP($D8,[1]계정코드!$A$5:$F$270,2,FALSE) -> #N/A | F8: =VLOOKUP($D8,[1]계정코드!$A$5:$F$270,4,FALSE) -> #N/A | K8: =K7+G8-H8 -> #REF!
E9: =VLOOKUP($D9,[1]계정코드!$A$5:$F$270,2,FALSE) -> #N/A | F9: =VLOOKUP($D9,[1]계정코드!$A$5:$F$270,4,FALSE) -> #N/A | K9: =K8+G9-H9 -> #REF!
E10: =VLOOKUP($D10,[1]계정코드!$A$5:$F$270,2,FALSE) -> #N/A | F10: =VLOOKUP($D10,[1]계정코드!$A$5:$F$270,4,FALSE) -> #N/A | K10: =K9+G10-H10 -> #REF!
E11: =VLOOKUP($D11,[1]계정코드!$A$5:$F$270,2,FALSE) -> #N/A | F11: =VLOOKUP($D11,[1]계정코드!$A$5:$F$270,4,FALSE) -> #N/A | K11: =K10+G11-H11 -> #REF!
E12: =VLOOKUP($D12,[1]계정코드!$A$5:$F$270,2,FALSE) -> #N/A | F12: =VLOOKUP($D12,[1]계정코드!$A$5:$F$270,4,FALSE) -> #N/A | K12: =K11+G12-H12 -> #REF!
E13: =VLOOKUP($D13,[1]계정코드!$A$5:$F$270,2,FALSE) -> #N/A | F13: =VLOOKUP($D13,[1]계정코드!$A$5:$F$270,4,FALSE) -> #N/A | K13: =K12+G13-H13 -> #REF!
E14: =VLOOKUP($D14,[1]계정코드!$A$5:$F$270,2,FALSE) -> #N/A | F14: =VLOOKUP($D14,[1]계정코드!$A$5:$F$270,4,FALSE) -> #N/A | K14: =K13+G14-H14 -> #REF!

Sheet 계정코드
A1: ◆ 창원교회 회계 계정코드
A3: 1. 수입 계정 | F3: 작성일 : 2020년 2월 5일
A4: 계정코드 | B4: 대분류계정항목 | C4: 중분류계정항목 | D4: 세부계정항목(예산안) | E4: 계정유형 | F4: 재정구분
A5: 11000 | B5: 십일조 | C5: 십일조 | E5: 헌금 | F5: 일반
A6: 11010 | B6: 십일조 외 | C6: 일반계정헌금 | D6: (십일조,주일, 감사등등 포함) | E6: 헌금 | F6: 일반
A7: 11100 | B7: 감사헌금 | C7: 감사헌금 | E7: 헌금 | F7: 일반
A8: 11200 | B8: 주일헌금 | C8: 주일헌금 | E8: 헌금 | F8: 일반
A9: 11300 | B9: 건축헌금 | C9: 건축헌금 | E9: 목적헌금 | F9: 건축
A10: 11310 | B10: 승강기헌금 | C10: 승강기헌금 | E10: 목적헌금 | F10: 건축
A11: 11400 | B11: 전도집회헌금 | C11: 전도집회헌금 | E11: 헌금 | F11: 일반
A12: 11500 | B12: 기타헌금 | C12: 회별헌금 | E12: 헌금 | F12: 일반
A13: 11510 | B13: 기타헌금 | C13: 회별헌금 | D13: 봉사회 | E13: 헌금 | F13: 일반
A14: 11520 | B14: 기타헌금 | C14: 회별헌금 | D14: 어머니회 | E14: 헌금 | F14: 일반
A15: 11530 | B15: 기타헌금 | C15: 회별헌금 | D15: 은장회 | E15: 헌금 | F15: 일반
A16: 11540 | B16: 기타헌금 | C16: 회별헌금 | D16: 청년회 | E16: 헌금 | F16: 일반
A17: 11550 | B17: 기타헌금 | C17: 회별헌금 | D17: 중고등부 | E17: 헌금 | F17: 일반
A18: 11560 | B18: 기타헌금 | C18: 회별헌금 | D18: 유초등부 | E18: 헌금 | F18: 일반
A19: 11600 | B19: 특별헌금 | C19: 특별헌금 | E19: 헌금 | F19: 일반
A20: 11610 | B20: 특별헌금 | C20: 특별헌금 | D20: 특별선교헌금 | E20: 헌금 | F20: 일반
A21: 11620 | B21: 특별헌금 | C21: 특별헌금 | D21: 특별지원헌금(형제,자매 재정지원) | E21: 헌금 | F21: 일반
A22: 11999 | B22: 기타헌금 | C22: 기타헌금 | E22: 헌금 | F22: 일반
A23: 12000 | B23: 선교회비 | C23: 선교회비 | E23: 목적헌금 | F23: 선교회
A24: 12100 | B24: 세계선교분담금 | C24: 세계선교분담금 | D24: 총회,분담금,퀘존/아르헨티나 | E24: 목적헌금 | F24: 선교회
A25: 12200 | B25: 세계선교헌금 | C25: 세계선교헌금 | D25: 총회 | E25: 목적헌금 | F25: 선교회
A26: 13000 | B26: 교회학교후원회비 | C26: 교회학교후원회비 | E26: 목적헌금 | F26: 후원회
A27: 13010 | B27: 교회학교후원회비 | C27: 교회학교후원회비 | D27: 후원회비 반환금 | E27: 목적헌금 | F27: 후원회
A28: 13020 | B28: 교회학교후원회비 | C28: 교회학교후원회비 | D28: 유초등부 및 중고등부 통합 후원회비 | E28: 수입 | F28: 일반
A29: 14000 | B29: 사랑의헌금 | C29: 사랑의헌금 | E29: 목적헌금 | F29: 사랑의 헌금
A30: 15000 | B30: 해외후원헌금 | C30: 해외후원헌금 | E30: 목적헌금 | F30: 해외후원 | H30: 2023신설
A31: 15100 | B31: 해외후원헌금 | C31: 해외후원헌금 | D31: 해외후원참여헌금 | E31: 목적헌금 | F31: 해외후원 | H31: 2023신설
A32: 15200 | B32: 해외후원헌금 | C32: 해외후원헌금 | D32: 필리핀퀘존권역헌금(김포,고창,세종중부) | E32: 목적헌금 | F32: 해외후원 | H32: 2023신설
A33: 15800 | B33: 해외후원헌금 | C33: 해외후원헌금 | D33: 아르헨티나 선교헌금 | E33: 목적헌금 | F33: 해외후원 | H33: 2024신설
A34: 15900 | B34: 해외후원헌금 | C34: 해외후원헌금 | D34: 기타 | E34: 목적헌금 | F34: 해외후원 | H34: 2023신설
A35: 16100 | B35: 국내선교 | C35: 국내선교헌금 | D35: 국내선교헌금(지역선교) | E35: 목적헌금 | F35: 국내선교 | H35: 2023신설
A36: 23000 | B36: 기타수입 | C36: 차입금 | E36: 부채 | F36: 건축
A37: 23010 | B37: 기타수입 | C37: 차입금 | D37: 차입금(은행) | E37: 부채 | F37: 건축
A38: 23020 | B38: 기타수입 | C38: 차입금 | D38: 차입금(사택담보) | E38: 부채 | F38: 일반
A39: 23030 | B39: 기타수입 | C39: 차입금 | D39: 차입금(은행-마산교회대여용) | E39: 부채 | F39: 건축
A40: 23100 | B40: 기타수입 | C40: 대여금회수 | E40: 자산 | F40: 일반
A41: 23110 | B41: 기타수입 | C41: 대여금회수 | D41: 지역교회(밀양교회)-대여금회수 | E41: 자산 | F41: 일반
...

Sheet 장부작성시 주의사항
A1: * 장부 작성시 주의 사항
A3: 1. 지정된 코드를 반드시 사용한다.
A4: 2. 새로운 코드 생성은 회계가 정한다. (필요시 회계담당자와 교제)
A5: 3. 적요 부분에서 같은 내용이라면 통일 시킬 것. (예- 주유비/ 주유금액- 같은 내용을 상이하게 하지 말것)
A6: 4. 지출결의번호 생성은 지출시점에 생성한다. (지출결의서 작성 후 시간이 지난 후 지출되면 일자 차이로 인하여 확인 애로사항 발생 추정)
A7: 20-0105-001 (연도-월일-순번)
